Workbook
Name _MailAutoSig: '1 - COT. RESUMEN'!$B$64

Sheet 2 - DESPIECE
G3: FECHA EMISION | H3: 45328
C6: COTIZACIÓN Nº
C8: PROYECTO | E8: KAUFMANN CASA MATRIZ PISO 1-3 | F8: R.U.T.
C9: CLIENTE | E9: KAUFMANN | F9: COMUNA | G9: ESTACION CENTRAL
C10: DIRECCIÓN | E10: AV. PAJARITOS 5830-ESTACION CENTRAL | F10: CIUDAD | G10: SANTIAGO
C11: REQUERIMIENTO MOBILIARIO | E11: SILLAS - ESCRITORIOS | F11: TELEFONO | G11: 9-54133485
C12: ENCARGADO SR/SRA: | E12: NELSON ALTAMIRANO | F12: EJECUTUVO | G12: PAOLA YANQUEZ
C13: FECHA | E13: 45355
C15: ITEM | D15: CODIGO | E15: DESCRIPCIÓN | F15: CANTIDAD | G15: PRECIO UNITARIO | H15: TOTAL
C16: 3 | D16: CUR25.15070.B | E16: CUBIERTA RECTA (25MM)DE 150 X 70 LAMINADO B | F16: 12 | G16: 139000 | H16: =+G16*F16 -> 1668000
C17: 5 | D17: INT_XXX | E17: ESTRUCTURA 3000x1400 | F17: 3 | H17: =+G17*F17 -> 0
C18: 6 | D18: OH11117 | E18: KIT BIOMBO TAPIZADO DE 150 X 30 TELA BRATTO | F18: =2*F17 -> 6 | G18: 192000 | H18: =+G18*F18 -> 1152000
C19: 7.3 | D19: CUR25.15070.B | E19: CUBIERTA RECTA (25MM)DE 150 X 70 LAMINADO B | F19: =6*F20 -> 24 | G19: 139000 | H19: =+G19*F19 -> 3336000
C20: 8.6 | D20: INT_XXX | E20: ESTRUCTURA 3000x1400 | F20: 4 | H20: =+G20*F20 -> 0
C21: 9.9 | D21: OH11117 | E21: KIT BIOMBO TAPIZADO DE 150 X 30 TELA BRATTO | F21: =3*F20 -> 12 | G21: 192000 | H21: =+G21*F21 -> 2304000
C22: 11.2 | D22: CUR25.130120.B | E22: CUBIERTA RECTA (25MM)DE 130 X 120 LAMINADO B | F22: 2 | G22: 162000 | H22: =+G22*F22 -> 324000
C23: 12.5 | D23: INT_XXX | E23: ESTRUCTURA 2500x1200 | F23: 1 | G23: 0 | H23: =+G23*F23 -> 0
C24: 21.6 | D24: CUR25.16070.B | E24: CUBIERTA RECTA (25MM)DE 160 X 70 LAMINADO B | F24: 2 | G24: 238000 | H24: =+G24*F24 -> 476000
C25: 22.9 | D25: INT1724 | E25: EST LIGHT 160X70 PF5050 C/PILOTE C/E MDLDBL | F25: =F24 -> 2 | G25: 188600 | H25: =+G25*F25 -> 377200
C26: 24.2 | D26: CUR25.15040.B | E26: CUBIERTA RECTA (25MM)DE 150 X 40 LAMINADO B FALDON | F26: 2 | G26: 68000 | H26: =+G26*F26 -> 136000
C27: 25.5 | D27: OH10394.M | E27: GABINETE LATERAL DE 120 X 53 X 62 FULL MELAMINA | F27: 2 | G27: 402000 | H27: =+G27*F27 -> 804000
C28: 26.8 | D28: INT_CAJA1X1 | E28: CAJA ELECTRICA SIMPLE-SIMPLE (1X1) | F28: 2 | G28: 44200 | H28: =+G28*F28 -> 88400
C29: 28.1 | D29: GBC.905073.B | E29: GABINETE BAJO C/CUBIERTA 2 PUERTAS DE 90 X 50 X 73 LAM B | F29: 4 | G29: 278000 | H29: =+G29*F29 -> 1112000
C30: 30.7 | D30: OH | E30: LOCKERS 12 PUERTAS ACUTALIZAR VALOR | F30: 3 | H30: =+G30*F30 -> 0
C31: 32 | D31: PG4730144.352 | E31: SILLA YON (47301)_SINCRO_BRAZO MC AZUL_RESP GRIS_ASTO GRIS | F31: 46 | G31: 421000 | H31: =+G31*F31 -> 19366000
C32: 33.3 | E32: SILLA GO | F32: 4 | H32: =+G32*F32 -> 0
C33: 34.6 | H33: =+G33*F33 -> 0
C34: 35.9 | H34: =+G34*F34 -> 0
C35: 37.2 | H35: =+G35*F35 -> 0
C36: 38.5 | H36: =+G36*F36 -> 0
G37: TOTAL | H37: =SUM(H16:H36) -> 31143600
G39: DESCUENTO 0 | H39: =+H37*0% -> 0
G40: SUBTOTAL | H40: =+H37-H39 -> 31143600
G41: FLETE 4% | H41: =+H40*4% -> 1245744
G42: INSTALACION 3% | H42: =+H40*3% -> 934308
G43: NETO | H43: =+H42+H41+H40 -> 33323652
G44: IVA 19% | H44: =+H43*19% -> 6331493.9
G45: TOTAL FINAL | H45: =+H44+H43 -> 39655146
B48: Condiciones Comerciales
B49: Aceptación de un proyecto
...

Sheet 1 - COT. RESUMEN
I3: FECHA EMISION | J3: 45313
C6: COTIZACIÓN Nº
C8: PROYECTO | F8: ='2 - DESPIECE'!E8 -> KAUFMANN CASA MATRIZ PISO 1-3 | G8: R.U.T. | H8: ='2 - DESPIECE'!G8:H8 -> 0
C9: CLIENTE | F9: ='2 - DESPIECE'!E9 -> KAUFMANN | G9: COMUNA | H9: ='2 - DESPIECE'!G9 -> ESTACION CENTRAL
C10: DIRECCIÓN | F10: ='2 - DESPIECE'!E10 -> AV. PAJARITOS 5830-ESTACION CENTRAL | G10: CIUDAD | H10: ='2 - DESPIECE'!G10 -> SANTIAGO
C11: REQUERIMIENTO MOBILIARIO | F11: ='2 - DESPIECE'!E11 -> SILLAS - ESCRITORIOS | G11: TELEFONO | H11: ='2 - DESPIECE'!G11:H11 -> 0
C12: ENCARGADO SR/SRA: | F12: ='2 - DESPIECE'!E12 -> NELSON ALTAMIRANO | G12: EJECUTUVO | H12: ='2 - DESPIECE'!G12 -> PAOLA YANQUEZ
C13: FECHA | F13: ='2 - DESPIECE'!E13 -> 45355
C15: Nº | D15: TIPO | E15: CODIGO | F15: DESCRIPCION | G15: CANTIDAD | H15: PRECIO UNITARIO | I15: TOTAL | J15: TOTAL TIPO
C16: 1 | I16: =+H16*G16 -> 0
C17: 2 | I17: =+H17*G17 -> 0
C18: 3 | I18: =+H18*G18 -> 0
C19: 4 | I19: =+H19*G19 -> 0
C20: 5 | I20: =+H20*G20 -> 0
C21: 6 | I21: =+H21*G21 -> 0
C22: 7 | I22: =+H22*G22 -> 0
C23: 8 | I23: =+H23*G23 -> 0
C24: 9 | I24: =+H24*G24 -> 0
C25: 10 | I25: =+H25*G25 -> 0
C26: 11 | I26: =+H26*G26 -> 0
C27: 12 | I27: =+H27*G27 -> 0
... C52: 37 | I52: =+H52*G52 -> 0
H53: TOTAL | I53: =SUM(I16:I52) -> 0 | J53: =SUM(J16:J52) -> 0
H55: DESCUENTO 15% | I55: =+I53*15% -> 0
H56: SUBTOTAL | I56: =+I53-I55 -> 0
H57: FLETE 4% | I57: =+I56*4% -> 0
H58: INSTALACION 3% | I58: =+I56*3% -> 0
H59: NETO | I59: =SUM(I56:I58) -> 0
H60: IVA 19% | I60: =+I59*19% -> 0
H61: TOTAL FINAL | I61: =SUM(I59:I60) -> 0
B64: Condiciones Comerciales
B65: Aceptación de un proyecto
B66: Se entenderá por aceptado el proyecto una vez que el cliente haya emitido una orden de compra (OC) por la cotización a Ohffice SpA, se firmen: los planos definitivos del proyecto, colores de terminaciones, tapices, para la fabricación de los productos y se haya cancelado el anticipo pactado en la cotización. Los productos de importación serán facturados al dólar observado del día de facturación. Solo una vez que se cuente con el anticipo, el proyecto pasa a etapa de fabricación.
B67: Rectificación
B68: Una vez recibida la OC del cliente, dentro de 2 días, nuestro personal calificado rectificará medidas en obra. Esto puede producir variaciones en productos, cantidades, valores y plazos de entregas que serán informados al cliente para su aprobación final. Si el cliente define no rectificar las medidas en terreno y trabajar solo en base a planimetría, cualquier variación de obra que provoquen modificaciones al mobiliario serán de responsabilidad y cargo exclusivo del cliente.
B69: Modificaciones
B70: Solo se aceptarán modificaciones posteriores a un proyecto aprobado, no instalado, si se acepta por escrito un nuevo presupuesto con las variaciones de productos solicitados y estos costos son asumidos por el cliente. Estas modificaciones aprobadas, deben considerar un plazo de entrega de 25 días hábiles, una vez aceptado el presupuesto.
B71: Despacho e Instalación
B72: El despacho e instalación de cada proyectos debe ser considerado y evaluado de forma particular de acuerdo a la ubicación, tipo de mercancía, ubicación, entre otros. No se despacharán ni instalarán productos mientras la obra no esté terminada. En caso de que el cliente lo exija, éste asume total responsabilidad por deterioro o daño de los productos. La instalación será realizada por personal de Ohffice, conforme con los planos firmados por el cliente en la aceptación del proyecto. Si el cliente quiere realizar la instalación por su propia cuenta, se exime de responsabilidad a Ohffice todo daño o deterioro en los productos. Toda modificación en la distribución debe ser realizada por escrito solo por el responsable del proyecto. En caso de que el cliente no pueda recibir en la fecha comprometida, Ohffice realizará un cargo por bodegaje de 0,3UF por día adicional a la fecha.
B73: Recepción Final
...
