Workbook

Sheet NOTA VENTA 1817
A1: NOTA DE VENTA 1817 Y SUS GUIAS
L2: GUIAS DESPACHADAS
A3: CodProd | B3: DesProd | C3: NVNumero | D3: VenCod | E3: nvEstado | F3: nvLinea | G3: nvFem | H3: CodGrupo | I3: CodSubGr | J3: Inventariable | K3: nvCant | L3: 7273 | M3: 7465 | N3: 7466 | O3: PDTE DESPACHO
A4: CF3607001.086 | B4: POLTRONA DUO(36174)_4 PATAS MADERA_(CEC) VERMELHO | C4: 1817 | D4: LCR | E4: A | F4: 1 | G4: 44295 | H4: 02 | I4: CAV | J4: -1 | K4: 6 | L4: =IFERROR(VLOOKUP(A4,GUIAS!$A$2:$R$6,4,0),0) -> 0 | M4: =IFERROR(VLOOKUP(A4,GUIAS!$A$7:$R$21,4,0),0) -> 6 | N4: =IFERROR(VLOOKUP(A4,GUIAS!$A$22:$R$36,4,0),0) -> 0 | O4: =K4-L4-M4-N4 -> 0
A5: MO1180136.24 | B5: MESA TALK (11801)_EST BLANCO ULTRA MATE_CUBIERTA ELMO SUIZO | C5: 1817 | D5: LCR | E5: A | F5: 2 | G5: 44295 | H5: 03 | I5: CAV | J5: -1 | K5: 3 | L5: =IFERROR(VLOOKUP(A5,GUIAS!$A$2:$R$6,4,0),0) -> 0 | M5: =IFERROR(VLOOKUP(A5,GUIAS!$A$7:$R$21,4,0),0) -> 3 | N5: =IFERROR(VLOOKUP(A5,GUIAS!$A$22:$R$36,4,0),0) -> 0 | O5: =K5-L5-M5-N5 -> 0
A6: CF3320601.117 | B6: SILLA FIJA STAY(32206)_PIE MADERA_PLAST BLANCO Y ASTO NARANJ | C6: 1817 | D6: LCR | E6: A | F6: 3 | G6: 44295 | H6: 01 | I6: CAV | J6: -1 | K6: 2 | L6: =IFERROR(VLOOKUP(A6,GUIAS!$A$2:$R$6,4,0),0) -> 0 | M6: =IFERROR(VLOOKUP(A6,GUIAS!$A$7:$R$21,4,0),0) -> 2 | N6: =IFERROR(VLOOKUP(A6,GUIAS!$A$22:$R$36,4,0),0) -> 0 | O6: =K6-L6-M6-N6 -> 0
A7: SB0368171.997 | B7: SOFA SPIN MOD RECTO(36814)_(VNL) EST ROJO_ASTO Y RESP BEIGE | C7: 1817 | D7: LCR | E7: A | F7: 4 | G7: 44295 | H7: 02 | I7: CAV | J7: -1 | K7: 2 | L7: =IFERROR(VLOOKUP(A7,GUIAS!$A$2:$R$6,4,0),0) -> 0 | M7: =IFERROR(VLOOKUP(A7,GUIAS!$A$7:$R$21,4,0),0) -> 2 | N7: =IFERROR(VLOOKUP(A7,GUIAS!$A$22:$R$36,4,0),0) -> 0 | O7: =K7-L7-M7-N7 -> 0
A8: SB3686568.997 | B8: MODULO RECTO 36.865 -650MM -ALTURA 820MM XPROFUNDIDAD 650MM | C8: 1817 | D8: LCR | E8: A | F8: 5 | G8: 44295 | H8: 02 | I8: CAV | J8: -1 | K8: 2 | L8: =IFERROR(VLOOKUP(A8,GUIAS!$A$2:$R$6,4,0),0) -> 0 | M8: =IFERROR(VLOOKUP(A8,GUIAS!$A$7:$R$21,4,0),0) -> 0 | N8: =IFERROR(VLOOKUP(A8,GUIAS!$A$22:$R$36,4,0),0) -> 2 | O8: =K8-L8-M8-N8 -> 0
A9: FG.183 | B9: MACETERO REDONDO FIBRA DE VIDRIO 60X50X30 | C9: 1817 | D9: LCR | E9: A | F9: 6 | G9: 44295 | J9: 0 | K9: 29 | L9: =IFERROR(VLOOKUP(A9,GUIAS!$A$2:$R$6,4,0),0) -> 29 | M9: =IFERROR(VLOOKUP(A9,GUIAS!$A$7:$R$21,4,0),0) -> 0 | N9: =IFERROR(VLOOKUP(A9,GUIAS!$A$22:$R$36,4,0),0) -> 0 | O9: =K9-L9-M9-N9 -> 0
A10: FG.121 | B10: MACETERO RECTANGULAR FIBRA DE VIDRIO_60X30X30 | C10: 1817 | D10: LCR | E10: A | F10: 7 | G10: 44295 | J10: 0 | K10: 4 | L10: =IFERROR(VLOOKUP(A10,GUIAS!$A$2:$R$6,4,0),0) -> 4 | M10: =IFERROR(VLOOKUP(A10,GUIAS!$A$7:$R$21,4,0),0) -> 0 | N10: =IFERROR(VLOOKUP(A10,GUIAS!$A$22:$R$36,4,0),0) -> 0 | O10: =K10-L10-M10-N10 -> 0
A11: SB0900282.125 | B11: POUF SPIN HEXAGONAL REGULAR BAJO_(VNL) EST GRAFITO Y ASTO AZ | C11: 1817 | D11: LCR | E11: A | F11: 8 | G11: 44295 | H11: 02 | I11: CAV | J11: -1 | K11: 2 | L11: =IFERROR(VLOOKUP(A11,GUIAS!$A$2:$R$6,4,0),0) -> 0 | M11: =IFERROR(VLOOKUP(A11,GUIAS!$A$7:$R$21,4,0),0) -> 0 | N11: =IFERROR(VLOOKUP(A11,GUIAS!$A$22:$R$36,4,0),0) -> 2 | O11: =K11-L11-M11-N11 -> 0
A12: SB0900282.117 | B12: POUF SPIN HEXAGONAL REGULAR BAJO_(VNL) EST GRAFITO Y ASTO NA | C12: 1817 | D12: LCR | E12: A | F12: 9 | G12: 44295 | H12: 02 | I12: CAV | J12: -1 | K12: 2 | L12: =IFERROR(VLOOKUP(A12,GUIAS!$A$2:$R$6,4,0),0) -> 0 | M12: =IFERROR(VLOOKUP(A12,GUIAS!$A$7:$R$21,4,0),0) -> 0 | N12: =IFERROR(VLOOKUP(A12,GUIAS!$A$22:$R$36,4,0),0) -> 2 | O12: =K12-L12-M12-N12 -> 0
A13: HR.MESBL01 | B13: MESA LATERAL CUP_ BLANCA | C13: 1817 | D13: LCR | E13: A | F13: 10 | G13: 44295 | H13: 03 | J13: 0 | K13: 5 | L13: =IFERROR(VLOOKUP(A13,GUIAS!$A$2:$R$6,4,0),0) -> 0 | M13: =IFERROR(VLOOKUP(A13,GUIAS!$A$7:$R$21,4,0),0) -> 5 | N13: =IFERROR(VLOOKUP(A13,GUIAS!$A$22:$R$36,4,0),0) -> 0 | O13: =K13-L13-M13-N13 -> 0
A14: SB0368183.997 | B14: SOFA SPIN MOD RECTO(36814)_(VNL) EST ROJO_ASTO Y RESP BEIGE | C14: 1817 | D14: LCR | E14: A | F14: 11 | G14: 44295 | H14: 02 | I14: CAV | J14: -1 | K14: 1 | L14: =IFERROR(VLOOKUP(A14,GUIAS!$A$2:$R$6,4,0),0) -> 0 | M14: =IFERROR(VLOOKUP(A14,GUIAS!$A$7:$R$21,4,0),0) -> 1 | N14: =IFERROR(VLOOKUP(A14,GUIAS!$A$22:$R$36,4,0),0) -> 0 | O14: =K14-L14-M14-N14 -> 0
A15: SB0368182.997 | B15: SOFA SPIN MOD RECTO(36814)_(VNL) EST GRAFITO_RESP Y ASTO AZU | C15: 1817 | D15: LCR | E15: A | F15: 12 | G15: 44295 | H15: 02 | I15: CAV | J15: -1 | K15: 1 | L15: =IFERROR(VLOOKUP(A15,GUIAS!$A$2:$R$6,4,0),0) -> 0 | M15: =IFERROR(VLOOKUP(A15,GUIAS!$A$7:$R$21,4,0),0) -> 1 | N15: =IFERROR(VLOOKUP(A15,GUIAS!$A$22:$R$36,4,0),0) -> 1 | O15: =K15-L15-M15-N15 -> -1
A16: SERV_T61 | B16: SERVICIO FLETE PUCV | C16: 1817 | D16: LCR | E16: A | F16: 13 | G16: 44295 | H16: 14 | J16: 0 | K16: 1 | L16: =IFERROR(VLOOKUP(A16,GUIAS!$A$2:$R$6,4,0),0) -> 0 | M16: =IFERROR(VLOOKUP(A16,GUIAS!$A$7:$R$21,4,0),0) -> 0 | N16: =IFERROR(VLOOKUP(A16,GUIAS!$A$22:$R$36,4,0),0) -> 1 | O16: =K16-L16-M16-N16 -> 0
A17: CF3607001.194 | B17: POLTRONA DUO(36174)_4 PATAS MADERA_(CEC) FENDI | C17: 1817 | D17: LCR | E17: A | F17: 14 | G17: 44295 | H17: 01 | I17: CAV | J17: -1 | K17: 10 | L17: =IFERROR(VLOOKUP(A17,GUIAS!$A$2:$R$6,4,0),0) -> 0 | M17: =IFERROR(VLOOKUP(A17,GUIAS!$A$7:$R$21,4,0),0) -> 10 | N17: =IFERROR(VLOOKUP(A17,GUIAS!$A$22:$R$36,4,0),0) -> 0 | O17: =K17-L17-M17-N17 -> 0
A18: MO1180121.24 | B18: MESA TALK 11801_ESTR GRAFITO_CUBIERTA ELMO SUIZO | C18: 1817 | D18: LCR | E18: A | F18: 15 | G18: 44295 | H18: 03 | I18: CAV | J18: -1 | K18: 12 | L18: =IFERROR(VLOOKUP(A18,GUIAS!$A$2:$R$6,4,0),0) -> 1 | M18: =IFERROR(VLOOKUP(A18,GUIAS!$A$7:$R$21,4,0),0) -> 11 | N18: =IFERROR(VLOOKUP(A18,GUIAS!$A$22:$R$36,4,0),0) -> 0 | O18: =K18-L18-M18-N18 -> 0
A19: CF3320601.125 | B19: SILLA FIJA STAY(33206) PIE MADERA_PLA BLANCO Y ASTO(VNL)AZUL | C19: 1817 | D19: LCR | E19: A | F19: 16 | G19: 44295 | H19: 01 | I19: CAV | J19: -1 | K19: 2 | L19: =IFERROR(VLOOKUP(A19,GUIAS!$A$2:$R$6,4,0),0) -> 0 | M19: =IFERROR(VLOOKUP(A19,GUIAS!$A$7:$R$21,4,0),0) -> 2 | N19: =IFERROR(VLOOKUP(A19,GUIAS!$A$22:$R$36,4,0),0) -> 0 | O19: =K19-L19-M19-N19 -> 0
A20: CF3320603.117 | B20: SILLA FIJA STAY( 33206 ) PIE MADERA_PLAS GRIS Y ASTO NARANJA | C20: 1817 | D20: LCR | E20: A | F20: 17 | G20: 44295 | H20: 01 | I20: CAV | J20: -1 | K20: 13 | L20: =IFERROR(VLOOKUP(A20,GUIAS!$A$2:$R$6,4,0),0) -> 0 | M20: =IFERROR(VLOOKUP(A20,GUIAS!$A$7:$R$21,4,0),0) -> 13 | N20: =IFERROR(VLOOKUP(A20,GUIAS!$A$22:$R$36,4,0),0) -> 0 | O20: =K20-L20-M20-N20 -> 0
A21: CF3320603.125 | B21: SILLA FIJA STAY(33206)_PIE MADERA_PLAS GRIS Y ASTO AZUL | C21: 1817 | D21: LCR | E21: A | F21: 18 | G21: 44295 | H21: 01 | I21: CAV | J21: -1 | K21: 15 | L21: =IFERROR(VLOOKUP(A21,GUIAS!$A$2:$R$6,4,0),0) -> 0 | M21: =IFERROR(VLOOKUP(A21,GUIAS!$A$7:$R$21,4,0),0) -> 15 | N21: =IFERROR(VLOOKUP(A21,GUIAS!$A$22:$R$36,4,0),0) -> 0 | O21: =K21-L21-M21-N21 -> 0
A22: SB0368183.997 | B22: SOFA SPIN MOD RECTO(36814)_(VNL) EST ROJO_ASTO Y RESP BEIGE | C22: 1817 | D22: LCR | E22: A | F22: 19 | G22: 44295 | H22: 02 | I22: CAV | J22: -1 | K22: 1 | L22: =IFERROR(VLOOKUP(A22,GUIAS!$A$2:$R$6,4,0),0) -> 0 | M22: =IFERROR(VLOOKUP(A22,GUIAS!$A$7:$R$21,4,0),0) -> 1 | N22: =IFERROR(VLOOKUP(A22,GUIAS!$A$22:$R$36,4,0),0) -> 0 | O22: =K22-L22-M22-N22 -> 0
A23: SB0368176.997 | B23: SOFA SPIN MOD RECTO(36814)_(VNL) EST Y ASTO GRAFITO_RESP AZU | C23: 1817 | D23: LCR | E23: A | F23: 20 | G23: 44295 | H23: 02 | I23: CAV | J23: -1 | K23: 1 | L23: =IFERROR(VLOOKUP(A23,GUIAS!$A$2:$R$6,4,0),0) -> 0 | M23: =IFERROR(VLOOKUP(A23,GUIAS!$A$7:$R$21,4,0),0) -> 1 | N23: =IFERROR(VLOOKUP(A23,GUIAS!$A$22:$R$36,4,0),0) -> 0 | O23: =K23-L23-M23-N23 -> 0
A24: SB0368174.997 | B24: SOFA SPIN MOD RECTO(36814)_(VNL) EST GRAFITO_RESP Y ASTO AZ | C24: 1817 | D24: LCR | E24: A | F24: 21 | G24: 44295 | H24: 02 | I24: CAV | J24: -1 | K24: 2 | L24: =IFERROR(VLOOKUP(A24,GUIAS!$A$2:$R$6,4,0),0) -> 0 | M24: =IFERROR(VLOOKUP(A24,GUIAS!$A$7:$R$21,4,0),0) -> 2 | N24: =IFERROR(VLOOKUP(A24,GUIAS!$A$22:$R$36,4,0),0) -> 0 | O24: =K24-L24-M24-N24 -> 0
A25: SB0368182.997 | B25: SOFA SPIN MOD RECTO(36814)_(VNL) EST GRAFITO_RESP Y ASTO AZU | C25: 1817 | D25: LCR | E25: A | F25: 22 | G25: 44295 | H25: 02 | I25: CAV | J25: -1 | K25: 1 | L25: =IFERROR(VLOOKUP(A25,GUIAS!$A$2:$R$6,4,0),0) -> 0 | M25: =IFERROR(VLOOKUP(A25,GUIAS!$A$7:$R$21,4,0),0) -> 1 | N25: =IFERROR(VLOOKUP(A25,GUIAS!$A$22:$R$36,4,0),0) -> 1 | O25: =K25-L25-M25-N25 -> -1
A26: SB0368181.997 | B26: SOFA SPIN MOD RECTO(36814)_(VNL) EST GRAFITO_RESP Y ASTO AZU | C26: 1817 | D26: LCR | E26: A | F26: 23 | G26: 44295 | H26: 02 | I26: CAV | J26: -1 | K26: 2 | L26: =IFERROR(VLOOKUP(A26,GUIAS!$A$2:$R$6,4,0),0) -> 0 | M26: =IFERROR(VLOOKUP(A26,GUIAS!$A$7:$R$21,4,0),0) -> 1 | N26: =IFERROR(VLOOKUP(A26,GUIAS!$A$22:$R$36,4,0),0) -> 0 | O26: =K26-L26-M26-N26 -> 1
A27: SB0368173.997 | B27: SOFA SPIN MOD RECTO(36814)_(VNL) EST Y RESP GRAF Y ASTO AZUL | C27: 1817 | D27: LCR | E27: A | F27: 24 | G27: 44295 | H27: 02 | I27: CAV | J27: -1 | K27: 1 | L27: =IFERROR(VLOOKUP(A27,GUIAS!$A$2:$R$6,4,0),0) -> 0 | M27: =IFERROR(VLOOKUP(A27,GUIAS!$A$7:$R$21,4,0),0) -> 0 | N27: =IFERROR(VLOOKUP(A27,GUIAS!$A$22:$R$36,4,0),0) -> 1 | O27: =K27-L27-M27-N27 -> 0
A28: SB0368177.997 | B28: SOFA SPIN MOD RECTO(36814)_(VNL) EST Y RESP GRAF Y ASTO AZUL | C28: 1817 | D28: LCR | E28: A | F28: 25 | G28: 44295 | H28: 02 | I28: CAV | J28: -1 | K28: 1 | L28: =IFERROR(VLOOKUP(A28,GUIAS!$A$2:$R$6,4,0),0) -> 0 | M28: =IFERROR(VLOOKUP(A28,GUIAS!$A$7:$R$21,4,0),0) -> 0 | N28: =IFERROR(VLOOKUP(A28,GUIAS!$A$22:$R$36,4,0),0) -> 1 | O28: =K28-L28-M28-N28 -> 0
... A46: SB0368175.997 | B46: SOFA SPIN MOD RECTO(36814)_(VNL)EST Y ASTO GRAFITO_RESP NARA | C46: 1817 | D46: LCR | E46: A | F46: 43 | G46: 44295 | H46: 02 | I46: CAV | J46: -1 | K46: 1 | L46: =IFERROR(VLOOKUP(A46,GUIAS!$A$2:$R$6,4,0),0) -> 0 | M46: =IFERROR(VLOOKUP(A46,GUIAS!$A$7:$R$21,4,0),0) -> 0 | N46: =IFERROR(VLOOKUP(A46,GUIAS!$A$22:$R$36,4,0),0) -> 1 | O46: =K46-L46-M46-N46 -> 0
A49: RESUMEN PRODUCTOS PENDIENTES DE DESPACHO
A50: CodProd | B50: DesProd | C50: NVNumero | D50: VenCod | E50: nvEstado | F50: nvLinea | G50: nvFem | H50: CodGrupo | I50: CodSubGr | J50: Inventariable | K50: nvCant | L50: 7273 | M50: 7465 | N50: 7466 | O50: Pdte-Desapcho | P50: OBS.LORETO
A51: SB0368175.997 | B51: SOFA SPIN MOD RECTO(36814)_(VNL)EST Y ASTO GRAFITO_RESP NARA | C51: 1817 | D51: LCR | E51: A | F51: 43 | G51: 44295 | H51: 02 | I51: CAV | J51: -1 | K51: 1 | L51: 0 | M51: 0 | N51: 0 | O51: =K51-L51-M51-N51 -> 1 | P51: SB0368175.997 = ítem 30 y 43 ambos solicitan 1 und cada uno pero fisicamente llego de Cavaletti 1 und ERA 1 un CON USB EN LADO IZQUIERDO Y 2 un SIN USB, ERROR DE CAVALETTI
A52: SB0368176.997 | B52: SOFA SPIN MOD RECTO(36814)_(VNL) EST Y ASTO GRAFITO_RESP AZU | C52: 1817 | D52: LCR | E52: A | F52: 36 | G52: 44295 | H52: 02 | I52: CAV | J52: -1 | K52: 1 | L52: 0 | M52: 0 | N52: 0 | O52: =K52-L52-M52-N52 -> 1 | P52: SB0368176.997 = ítem 20 – 36-40 todos ellos solicitan 1 und cada uno pero fisicamente llego de Cavaletti 1 sola und ESTÁ OK, ES 1 UNIDAD DE BASE Y ASIENTO GRAFITO RESPALDO AZUL CON USB EN LADO DERECHO. ESTÁN MAL LOS CODIGOS DE NV
A53: SB0368176.997 | B53: SOFA SPIN MOD RECTO(36814)_(VNL) EST Y ASTO GRAFITO_RESP AZU | C53: 1817 | D53: LCR | E53: A | F53: 40 | G53: 44295 | H53: 02 | I53: CAV | J53: -1 | K53: 2 | L53: 0 | M53: 0 | N53: 0 | O53: =K53-L53-M53-N53 -> 2 | P53: SB0368176.997 = ítem 20 – 36-40 todos ellos solicitan 1 und cada uno pero fisicamente llego de Cavaletti 1 sola und ESTÁ OK, ES 1 UNIDAD DE BASE Y ASIENTO GRAFITO RESPALDO AZUL CON USB EN LADO DERECHO. ESTÁN MAL LOS CODIGOS DE NV
A54: SB0368177.997 | B54: SOFA SPIN MOD RECTO(36814)_(VNL) EST Y RESP GRAF Y ASTO AZUL | C54: 1817 | D54: LCR | E54: A | F54: 41 | G54: 44295 | H54: 02 | I54: CAV | J54: -1 | K54: 1 | L54: 0 | M54: 0 | N54: 0 | O54: =K54-L54-M54-N54 -> 1 | P54: SB0368177.997 = ítem 25 y 41 ambos solicitan 1 und cada uno pero fisicamente llego de Cavaletti 1 und ERA 1 un CON USB EN LADO DERECHO, ESTÁN MAL LOS CÓDIGOS DE NV
A55: SB0368178.997 | B55: SOFA SPIN MOD RECTO(36814)_(VNL) EST Y RESP GRAFITO_ASTO NAR | C55: 1817 | D55: LCR | E55: A | F55: 39 | G55: 44295 | H55: 02 | I55: CAV | J55: -1 | K55: 1 | L55: 0 | M55: 0 | N55: 0 | O55: =K55-L55-M55-N55 -> 1 | P55: SB0368178.997 = ítem 32y 39 ambos solicitan 1 und cada uno pero fisicamente llego de Cavaletti 1 und ERA 1 un CON USB EN LADO IZQUIERDO Y 1 un SIN USB, ERROR DE CAVALETTI
A56: SB0368179.997 | B56: SOFA SPIN MOD RECTO(36814)_(VNL) EST GRAFITO_ASTO Y RESP NAR | C56: 1817 | D56: LCR | E56: A | F56: 38 | G56: 44295 | H56: 02 | I56: CAV | J56: -1 | K56: 1 | L56: 0 | M56: 0 | N56: 0 | O56: =K56-L56-M56-N56 -> 1 | P56: SB0368179.997 = ítem 28 y 38 ambos solicitan 1 und cada uno pero físicamente llego de Cavaletti 1 und ERA 1 un CON USB IZQUIERDO Y 1 un CON USB DERECHO, ERROR DE CAVALETTI
A57: SB0368180.997 | B57: SOFA SPIN MOD RECTO(36814)_(VNL) EST GRAFITO_ASTO Y RESP NAR | C57: 1817 | D57: LCR | E57: A | F57: 42 | G57: 44295 | H57: 02 | I57: CAV | J57: -1 | K57: 1 | L57: 0 | M57: 0 | N57: 0 | O57: =K57-L57-M57-N57 -> 1 | P57: SB0368180.997 = ítem 29 y 42 ambos solicitan 1 und cada uno pero fisicamente llego de Cavaletti 1 und ERA 1 un CON USB LADO DERECHO Y 1 un CON USB LADO IZQUIERDO, ERROR DE CAVALETTI
A58: SB0368181.997 | B58: SOFA SPIN MOD RECTO(36814)_(VNL) EST GRAFITO_RESP Y ASTO AZU | C58: 1817 | D58: LCR | E58: A | F58: 23 | G58: 44295 | H58: 02 | I58: CAV | J58: -1 | K58: 3 | L58: 0 | M58: 0 | N58: 0 | O58: 3 | P58: SB0368181.997 = ítem 23 y 37 ambos solicitan 2 unds cada uno pero solo llego 1 und fisicamente aunque venia informado que eran 2 unds , se dio aviso de inmediato a gerencia y aun Cavaletti no lo ha repuesto ERA 1 UNIDAD, VER CURSE, ESTÁN MAL CODIGOS DE NV
A59: SB0368183.997 | B59: SOFA SPIN MOD RECTO(36814)_(VNL) EST ROJO_ASTO Y RESP BEIGE | C59: 1817 | D59: LCR | E59: A | F59: 19 | G59: 44295 | H59: 02 | I59: CAV | J59: -1 | K59: 1 | L59: 0 | M59: 0 | N59: 0 | O59: =K59-L59-M59-N59 -> 1 | P59: SB0368183.997 = ítem 11 y 19 ambos solicitan 1 und cada uno pero fisicamente llego de Cavaletti 1 sola und ERAN 2, 1 un SIN PUERTO USB Y 1 un CON USB EN LADO DERECHO, ERROR CAVALETTI
...

Sheet GUIAS
A1: CodProd | B1: DesProd | C1: CantIngresada | D1: CantDespachada | E1: Folio | F1: Linea | G1: PreUniMB | H1: PorcDescMov01 | I1: TotalDescMov | J1: TotLinea | K1: Tipo | L1: Concepto | M1: DesCodDr | N1: Estado | O1: CodVendedor | P1: Fecha | Q1: CodAux | R1: CentroDeCosto
A2: FG.183 | B2: MACETERO REDONDO FIBRA DE VIDRIO 60X50X30 | C2: 0 | D2: 29 | E2: 7273 | F2: 1 | G2: 149600 | H2: 0 | I2: 0 | J2: 4338400 | K2: S | L2: 01 | M2: Despacho por Facturar | N2: V | O2: LCR | P2: 44319 | Q2: 816692008 | R2: 03-01817
A3: FG.121 | B3: MACETERO RECTANGULAR FIBRA DE VIDRIO_60X30X30 | C3: 0 | D3: 4 | E3: 7273 | F3: 2 | G3: 129625 | H3: 0 | I3: 0 | J3: 518500 | K3: S | L3: 01 | M3: Despacho por Facturar | N3: V | O3: LCR | P3: 44319 | Q3: 816692008 | R3: 03-01817
A4: MO1180121.24 | B4: MESA TALK 11801_ESTR GRAFITO_CUBIERTA ELMO SUIZO | C4: 0 | D4: 1 | E4: 7273 | F4: 3 | G4: 62570 | H4: 0 | I4: 0 | J4: 62570 | K4: S | L4: 01 | M4: Despacho por Facturar | N4: V | O4: LCR | P4: 44319 | Q4: 816692008 | R4: 03-01817
A5: SB0368170.997 | B5: SOFA SPIN MOD RECTO (36814)_(VNL) EST GRAFITO_(VNL) ASTO Y R | C5: 0 | D5: 3 | E5: 7273 | F5: 4 | G5: 475345 | H5: 0 | I5: 0 | J5: 1426035 | K5: S | L5: 01 | M5: Despacho por Facturar | N5: V | O5: LCR | P5: 44319 | Q5: 816692008 | R5: 03-01817
A6: SB0368169.997 | B6: SOFA SPIN MOD RECTO (36814)_(VNL) EST Y ASTO GRAFITO_(VNL) | C6: 0 | D6: 1 | E6: 7273 | F6: 5 | G6: 475345 | H6: 0 | I6: 0 | J6: 475345 | K6: S | L6: 01 | M6: Despacho por Facturar | N6: V | O6: LCR | P6: 44319 | Q6: 816692008 | R6: 03-01817
A7: CF3607001.086 | B7: POLTRONA DUO(36174)_4 PATAS MADERA_(CEC) VERMELHO | C7: 0 | D7: 6 | E7: 7465 | F7: 1 | G7: 323235 | H7: 0 | I7: 0 | J7: 1939410 | K7: S | L7: 01 | M7: Despacho por Facturar | N7: V | O7: LCR | P7: 44382 | Q7: 816692008 | R7: 03-01817
A8: MO1180136.24 | B8: MESA TALK (11801)_EST BLANCO ULTRA MATE_CUBIERTA ELMO SUIZO | C8: 0 | D8: 3 | E8: 7465 | F8: 2 | G8: 62570 | H8: 0 | I8: 0 | J8: 187710 | K8: S | L8: 01 | M8: Despacho por Facturar | N8: V | O8: LCR | P8: 44382 | Q8: 816692008 | R8: 03-01817
A9: CF3320601.117 | B9: SILLA FIJA STAY(32206)_PIE MADERA_PLAST BLANCO Y ASTO NARANJ | C9: 0 | D9: 2 | E9: 7465 | F9: 3 | G9: 163811 | H9: 0 | I9: 0 | J9: 327622 | K9: S | L9: 01 | M9: Despacho por Facturar | N9: V | O9: LCR | P9: 44382 | Q9: 816692008 | R9: 03-01817
A10: SB0368171.997 | B10: SOFA SPIN MOD RECTO(36814)_(VNL) EST ROJO_ASTO Y RESP BEIGE | C10: 0 | D10: 2 | E10: 7465 | F10: 4 | G10: 441968 | H10: 0 | I10: 0 | J10: 883936 | K10: S | L10: 01 | M10: Despacho por Facturar | N10: V | O10: LCR | P10: 44382 | Q10: 816692008 | R10: 03-01817
A11: HR.MESBL01 | B11: MESA LATERAL CUP_ BLANCA | C11: 0 | D11: 5 | E11: 7465 | F11: 5 | G11: 53554 | H11: 0 | I11: 0 | J11: 267770 | K11: S | L11: 01 | M11: Despacho por Facturar | N11: V | O11: LCR | P11: 44382 | Q11: 816692008 | R11: 03-01817
A12: SB0368183.997 | B12: SOFA SPIN MOD RECTO(36814)_(VNL) EST ROJO_ASTO Y RESP BEIGE | C12: 0 | D12: 1 | E12: 7465 | F12: 6 | G12: 567021 | H12: 0 | I12: 0 | J12: 567021 | K12: S | L12: 01 | M12: Despacho por Facturar | N12: V | O12: LCR | P12: 44382 | Q12: 816692008 | R12: 03-01817
A13: SB0368182.997 | B13: SOFA SPIN MOD RECTO(36814)_(VNL) EST GRAFITO_RESP Y ASTO AZU | C13: 0 | D13: 1 | E13: 7465 | F13: 7 | G13: 567021 | H13: 0 | I13: 0 | J13: 567021 | K13: S | L13: 01 | M13: Despacho por Facturar | N13: V | O13: LCR | P13: 44382 | Q13: 816692008 | R13: 03-01817
... A36: SB0900283.117 | B36: POUF SPIN HEXAGONAL REGULAR MEDI_(VNL) EST GRAFITO Y ASTO NA | C36: 0 | D36: 2 | E36: 7466 | F36: 15 | G36: 171387 | H36: 0 | I36: 0 | J36: 342774 | K36: S | L36: 01 | M36: Despacho por Facturar | N36: V | O36: LCR | P36: 44382 | Q36: 816692008 | R36: 03-01817
